<?xml version="1.0" encoding="utf-8"?>
<!-- This URDF was automatically created by SolidWorks to URDF Exporter! Originally created by Stephen Brawner (brawner@gmail.com) 
     Commit Version: 1.5.1-0-g916b5db  Build Version: 1.5.7152.31018
     For more information, please see http://wiki.ros.org/sw_urdf_exporter -->
<robot
  name="401pius">
  <link name="base_footprint">
      <visual>
        <geometry>
          <sphere radius="0.001" />
        </geometry>
      </visual>
    </link>
  <link
    name="chejia_link">
    <inertial>
      <origin
        xyz="0.00361762800581263 -0.133421165022722 0.0648164589836014"
        rpy="0 0 0" />
      <mass
        value="2.424" />
      <inertia
        ixx="0.03"
        ixy="0"
        ixz="0"
        iyy="0.03"
        iyz="0"
        izz="0.006" />
    </inertial>
    <visual>
      <origin
        xyz="0 0 0"
        rpy="0 0 -1.57" />
      <geometry>
        <mesh
          filename="package://401pius/meshes/chejia_link.STL" />
      </geometry>
      <material
        name="">
        <color
          rgba="0.792156862745098 0.819607843137255 0.933333333333333 1" />
      </material>
    </visual>
    <collision>
      <origin
        xyz="0 0 0"
        rpy="0 0 0" />
      <geometry>
        <mesh
          filename="package://401pius/meshes/chejia_link.STL" />
      </geometry>
    </collision>
  </link>

  <joint name="chejia_link2base_footprint" type="fixed">
    <parent link="base_footprint" />
    <child link="chejia_link" />
    <origin xyz="0 0 0.33" />
  </joint>
  

  <link
    name="zhuanxiangjia_Link">
    <inertial>
      <origin
        xyz="0.00350625991709064 -0.184876810131571 -0.22368381667265"
        rpy="0 0 0" />
      <mass
        value="0.637" />
      <inertia
        ixx="0.0005"
        ixy="0"
        ixz="0"
        iyy="0.0007"
        iyz="0"
        izz="0.0006" />
    </inertial>
    <visual>
      <origin
        xyz="0 0 0"
        rpy="0 0 0" />
      <geometry>
        <mesh
          filename="package://401pius/meshes/zhuanxiangjia_Link.STL" />
      </geometry>
      <material
        name="">
        <color
          rgba="0.792156862745098 0.819607843137255 0.933333333333333 1" />
      </material>
    </visual>
    <collision>
      <origin
        xyz="0 0 0"
        rpy="0 0 0" />
      <geometry>
        <mesh
          filename="package://401pius/meshes/zhuanxiangjia_Link.STL" />
      </geometry>
    </collision>
  </link>
  <joint
    name="zhuanxiangjia_joint"
    type="revolute">
    <origin
      xyz="0 0 0"
      rpy="1.5708 0 -1.57" />
    <parent
      link="chejia_link" />
    <child
      link="zhuanxiangjia_Link" />
    <axis
      xyz="0 -1 0" />
    <limit
      lower="0"
      upper="0"
      effort="0"
      velocity="0" />
  </joint>
  <link
    name="zuoqianlun_Link">
    <inertial>
      <origin
        xyz="-0.18003195018567 0.0161203758776952 -0.0161713179715041"
        rpy="0 0 0" />
      <mass
        value="0.379" />
      <inertia
        ixx="0.0014"
        ixy="0"
        ixz="0"
        iyy="0.0007"
        iyz="0"
        izz="0.0007" />
    </inertial>
    <visual>
      <origin
        xyz="0 0 0"
        rpy="0 0 0" />
      <geometry>
        <mesh
          filename="package://401pius/meshes/zuoqianlun_Link.STL" />
      </geometry>
      <material
        name="">
        <color
          rgba="0.792156862745098 0.819607843137255 0.933333333333333 1" />
      </material>
    </visual>
    <collision>
      <origin
        xyz="0 0 0"
        rpy="0 0 0" />
      <geometry>
        <mesh
          filename="package://401pius/meshes/zuoqianlun_Link.STL" />
      </geometry>
    </collision>
  </link>
  <joint
    name="zuoqianlun_joint"
    type="continuous">
    <origin
      xyz="-0.092435 -0.21283 -0.24243"
      rpy="2.9877 0 0" />
    <parent
      link="zhuanxiangjia_Link" />
    <child
      link="zuoqianlun_Link" />
    <axis
      xyz="1 0 0" />
  </joint>
  <link
    name="youqianlun_Link">
    <inertial>
      <origin
        xyz="-0.180031949902314 0.0161203458684245 -0.0161712883250444"
        rpy="0 0 0" />
      <mass
        value="0.379" />
      <inertia
        ixx="0.0014"
        ixy="0"
        ixz="0"
        iyy="0.0007"
        iyz="0"
        izz="0.0007" />
    </inertial>
    <visual>
      <origin
        xyz="0 0 0"
        rpy="0 0 0" />
      <geometry>
        <mesh
          filename="package://401pius/meshes/youqianlun_Link.STL" />
      </geometry>
      <material
        name="">
        <color
          rgba="0.792156862745098 0.819607843137255 0.933333333333333 1" />
      </material>
    </visual>
    <collision>
      <origin
        xyz="0 0 0"
        rpy="0 0 0" />
      <geometry>
        <mesh
          filename="package://401pius/meshes/youqianlun_Link.STL" />
      </geometry>
    </collision>
  </link>
  <joint
    name="youqianlun_joint"
    type="continuous">
    <origin
      xyz="0.099447 -0.24433 -0.20905"
      rpy="-1.6671 0 3.1416" />
    <parent
      link="zhuanxiangjia_Link" />
    <child
      link="youqianlun_Link" />
    <axis
      xyz="1 0 0" />
  </joint>
  <link
    name="zuohoulun_Link">
    <inertial>
      <origin
        xyz="-0.205721407122161 4.72112875317676E-05 9.00201436271342E-06"
        rpy="0 0 0" />
      <mass
        value="0.635" />
      <inertia
        ixx="0.002"
        ixy="0"
        ixz="0"
        iyy="0.001"
        iyz="0"
        izz="0.001" />
    </inertial>
    <visual>
      <origin
        xyz="0 0 0"
        rpy="0 0 0" />
      <geometry>
        <mesh
          filename="package://401pius/meshes/zuohoulun_Link.STL" />
      </geometry>
      <material
        name="">
        <color
          rgba="0.792156862745098 0.819607843137255 0.933333333333333 1" />
      </material>
    </visual>
    <collision>
      <origin
        xyz="0 0 0"
        rpy="0 0 0" />
      <geometry>
        <mesh
          filename="package://401pius/meshes/zuohoulun_Link.STL" />
      </geometry>
    </collision>
  </link>
  <joint
    name="zuohoulun_joint"
    type="continuous">
    <origin
      xyz="-0.23219 0.058831 -0.22848"
      rpy="1.5708 0 -1.57" />
    <parent
      link="chejia_link" />
    <child
      link="zuohoulun_Link" />
    <axis
      xyz="1 0 0" />
  </joint>
  <link
    name="youhoulun_Link">
    <inertial>
      <origin
        xyz="-0.205721415016193 4.72492608288855E-05 9.01686700283122E-06"
        rpy="0 0 0" />
      <mass
        value="0.635" />
      <inertia
        ixx="0.002"
        ixy="0"
        ixz="0"
        iyy="0.001"
        iyz="0"
        izz="0.001" />
    </inertial>
    <visual>
      <origin
        xyz="0 0 0"
        rpy="0 0 0" />
      <geometry>
        <mesh
          filename="package://401pius/meshes/youhoulun_Link.STL" />
      </geometry>
      <material
        name="">
        <color
          rgba="0.792156862745098 0.819607843137255 0.933333333333333 1" />
      </material>
    </visual>
    <collision>
      <origin
        xyz="0 0 0"
        rpy="0 0 0" />
      <geometry>
        <mesh
          filename="package://401pius/meshes/youhoulun_Link.STL" />
      </geometry>
    </collision>
  </link>
  <joint
    name="youhoulun_joint"
    type="continuous">
    <origin
      xyz="-0.23219 -0.060844 -0.22848"
      rpy="0.17453 0 1.5708" />
    <parent
      link="chejia_link" />
    <child
      link="youhoulun_Link" />
    <axis
      xyz="1 0 0" />
  </joint>

  <transmission name="zuoqianlun_joint_trans">
    <type>transmission_interface/SimpleTransmission</type>
    <joint name="zuoqianlun_joint">
        <hardwareInterface>hardware_interface/VelocityJointInterface</hardwareInterface>
    </joint>
    <actuator name="zuoqianlun_joint_motor">
        <hardwareInterface>hardware_interface/VelocityJointInterface</hardwareInterface>
        <mechanicalReduction>1</mechanicalReduction>
    </actuator>
  </transmission>

    <transmission name="youqianlun_joint_trans">
    <type>transmission_interface/SimpleTransmission</type>
    <joint name="youqianlun_joint">
        <hardwareInterface>hardware_interface/VelocityJointInterface</hardwareInterface>
    </joint>
    <actuator name="youqianlun_joint_motor">
        <hardwareInterface>hardware_interface/VelocityJointInterface</hardwareInterface>
        <mechanicalReduction>1</mechanicalReduction>
    </actuator>
  </transmission>

    <transmission name="zuohoulun_joint_trans">
    <type>transmission_interface/SimpleTransmission</type>
    <joint name="zuohoulun_joint">
        <hardwareInterface>hardware_interface/VelocityJointInterface</hardwareInterface>
    </joint>
    <actuator name="zuohoulun_joint_motor">
        <hardwareInterface>hardware_interface/VelocityJointInterface</hardwareInterface>
        <mechanicalReduction>1</mechanicalReduction>
    </actuator>
  </transmission>

    <transmission name="youhoulun_joint_trans">
    <type>transmission_interface/SimpleTransmission</type>
    <joint name="youhoulun_joint">
        <hardwareInterface>hardware_interface/VelocityJointInterface</hardwareInterface>
    </joint>
    <actuator name="youhoulun_joint_motor">
        <hardwareInterface>hardware_interface/VelocityJointInterface</hardwareInterface>
        <mechanicalReduction>1</mechanicalReduction>
    </actuator>
  </transmission>

  <!-- <gazebo>
    <plugin name="skid_steer_drive_controller" filename="libgazebo_ros_skid_steer_drive.so">
        <updateRate>100.0</updateRate>
        <robotNamespace>/</robotNamespace>
        <leftFrontJoint>zuoqianlun_joint</leftFrontJoint>
        <rightFrontJoint>youqianlun_joint</rightFrontJoint>
        <leftRearJoint>zuohoulun_joint</leftRearJoint>
        <rightRearJoint>yuohoulun_joint</rightRearJoint>
        <wheelSeparation>0.545</wheelSeparation>
        <wheelDiameter>0.216</wheelDiameter>
        <robotBaseFrame>base_footprint</robotBaseFrame>
        <torque>20</torque>
        <topicName>cmd_vel</topicName>
        <broadcastTF>false</broadcastTF>
        <odometryFrame>odom</odometryFrame>
        <odometryTopic>odom</odometryTopic> 
       
    </plugin>
  </gazebo> -->

  <gazebo>
        <plugin name="differential_drive_controller" filename="libgazebo_ros_diff_drive.so">
            <rosDebugLevel>Debug</rosDebugLevel>
            <publishWheelTF>true</publishWheelTF>
            <robotNamespace>/</robotNamespace>
            <publishTf>1</publishTf>
            <publishWheelJointState>true</publishWheelJointState>
            <alwaysOn>true</alwaysOn>
            <updateRate>100.0</updateRate>
            <legacyMode>true</legacyMode>
            <leftJoint>zuohoulun_joint</leftJoint> 
            <rightJoint>yuohoulun_joint</rightJoint> 
            <wheelSeparation>0.545</wheelSeparation> 
            <wheelDiameter>0.216</wheelDiameter> 
            <broadcastTF>1</broadcastTF>
            <wheelTorque>30</wheelTorque>
            <wheelAcceleration>1.8</wheelAcceleration>
            <commandTopic>cmd_vel</commandTopic> 
            <odometryFrame>odom</odometryFrame>
            <odometryTopic>odom</odometryTopic> 
            <robotBaseFrame>base_footprint</robotBaseFrame> 
        </plugin>
    </gazebo>

</robot>