<?xml version="1.0" encoding="utf-8"?>
<!-- This URDF was automatically created by SolidWorks to URDF Exporter! Originally created by Stephen Brawner (brawner@gmail.com) 
     Commit Version: 1.5.1-0-g916b5db  Build Version: 1.5.7152.31018
     For more information, please see http://wiki.ros.org/sw_urdf_exporter -->
<robot
  name="segway_e1_description">
  <link name="base_link"/>

  <link name="base_footprint">
      <visual>
        <geometry>
          <sphere radius="0.001" />
        </geometry>
      </visual>
  </link>
  
  <joint name="base_link2base_footprint" type="fixed">
    <parent link="base_footprint" />
    <child link="base_link" />
    <origin xyz="0 0 0.19" />
  </joint>

  <link
    name="Chassis body">
    <inertial>
      <origin
        xyz="-0.033482 0.22487 0.0057368"
        rpy="0 0 1.57" />
      <mass
        value="1.5" />
      <inertia
        ixx="0.05"
        ixy="0"
        ixz="0"
        iyy="0.007"
        iyz="0"
        izz="0.052" />
    </inertial>
    <visual>
      <origin
        xyz="0 0 0"
        rpy="0 0 0" />
      <geometry>
        <mesh
          filename="package://segway_e1_description/meshes/Chassis body.STL" />
      </geometry>
      <material
        name="">
        <color
          rgba="0.79216 0.81961 0.93333 1" />
      </material>
    </visual>
    <collision>
      <origin
        xyz="0 0 0"
        rpy="0 0 0" />
      <geometry>
        <mesh
          filename="package://segway_e1_description/meshes/Chassis body.STL" />
      </geometry>
    </collision>
  </link>
  <joint name="base_joint" type="fixed">
    <origin xyz="0 0 0" rpy="0 0 -1.57" />
    <parent link="base_link"/>
    <child link="Chassis body"/>
  </joint>

  <link
    name="Left_rear_wheel">
    <inertial>
      <origin
        xyz="-7.8407E-07 -2.4326E-05 0.002005"
        rpy="0 0 0" />
      <mass
        value="1.25" />
      <inertia
        ixx="0.0049"
        ixy="0"
        ixz="0"
        iyy="0.005"
        iyz="0"
        izz="0.0087" />
    </inertial>
    <visual>
      <origin
        xyz="0 0 0"
        rpy="0 0 0" />
      <geometry>
        <mesh
          filename="package://segway_e1_description/meshes/Wheel.STL" />
      </geometry>
      <material
        name="">
        <color
          rgba="0.79216 0.81961 0.93333 1" />
      </material>
    </visual>
    <collision>
      <origin
        xyz="0 0 0"
        rpy="0 0 0" />
      <geometry>
        <mesh
          filename="package://segway_e1_description/meshes/Wheel.STL" />
      </geometry>
    </collision>
  </link>
  <joint
    name="Left_rear_wheel_joint"
    type="continuous">
    <origin
      xyz="-0.30884 0.04815 -0.080406"
      rpy="1.5708 0 1.5708" />
    <parent
      link="Chassis body" />
    <child
      link="Left_rear_wheel" />
    <axis
      xyz="0 0 -1" />
  </joint>
  <link
    name="Right_rear_wheel">
    <inertial>
      <origin
        xyz="4.9952E-06 2.3117E-05 0.0019578"
        rpy="0 0 0" />
      <mass
        value="1.25" />
      <inertia
        ixx="0.0049"
        ixy="0"
        ixz="0"
        iyy="0.005"
        iyz="0"
        izz="0.0087" />
    </inertial>
    <visual>
      <origin
        xyz="0 0 0"
        rpy="0 3.14 0" />
      <geometry>
        <mesh
          filename="package://segway_e1_description/meshes/Wheel.STL" />
      </geometry>
      <material
        name="">
        <color
          rgba="0.79216 0.81961 0.93333 1" />
      </material>
    </visual>
    <collision>
      <origin
        xyz="0 0 0"
        rpy="0 0 0" />
      <geometry>
        <mesh
          filename="package://segway_e1_description/meshes/Wheel.STL" />
      </geometry>
    </collision>
  </link>
  <joint
    name="Right_rear_wheel_joint"
    type="continuous">
    <origin
      xyz="0.24188 0.04815 -0.080406"
      rpy="1.5708 0 1.5708" />
    <parent
      link="Chassis body" />
    <child
      link="Right_rear_wheel" />
    <axis
      xyz="0 0 -1" />
  </joint>
  <link
    name="Chassis_front_beam">
    <inertial>
      <origin
        xyz="-8.6161E-10 3.9501E-05 0.0062593"
        rpy="0 0 0" />
      <mass
        value="0.48416" />
      <inertia
        ixx="0.0005"
        ixy="0"
        ixz="0"
        iyy="0.0024"
        iyz="0"
        izz="0.0024" />
    </inertial>
    <visual>
      <origin
        xyz="0 0 0"
        rpy="0 0 0" />
      <geometry>
        <mesh
          filename="package://segway_e1_description/meshes/Chassis front beam.STL" />
      </geometry>
      <material
        name="">
        <color
          rgba="0.79216 0.81961 0.93333 1" />
      </material>
    </visual>
    <collision>
      <origin
        xyz="0 0 0"
        rpy="0 0 0" />
      <geometry>
        <mesh
          filename="package://segway_e1_description/meshes/Chassis front beam.STL" />
      </geometry>
    </collision>
  </link>
  <joint
    name="Chassis_front_beam_joint"
    type="revolute">
    <origin
      xyz="-0.0335 0.504 -0.0515"
      rpy="0 0 0" />
    <parent
      link="Chassis body" />
    <child
      link="Chassis_front_beam" />
    <axis
      xyz="0 0 1" />
    <limit
      lower="-0.3"
      upper="0.3"
      effort="0"
      velocity="0" />
  </joint>
  <link
    name="Right_front_wheel">
    <inertial>
      <origin
        xyz="-7.0112E-05 8.4133E-05 0.54476"
        rpy="0 0 0" />
      <mass
        value="1.25" />
      <inertia
        ixx="0.0049"
        ixy="0"
        ixz="0"
        iyy="0.005"
        iyz="0"
        izz="0.0087" />
    </inertial>
    <visual>
      <origin
        xyz="0 0 0.017"
        rpy="0 3.14 0" />
      <geometry>
        <mesh
          filename="package://segway_e1_description/meshes/Wheel.STL" />
      </geometry>
      <material
        name="">
        <color
          rgba="0.79216 0.81961 0.93333 1" />
      </material>
    </visual>
    <collision>
      <origin
        xyz="0 0 0"
        rpy="0 0 0" />
      <geometry>
        <mesh
          filename="package://segway_e1_description/meshes/Wheel.STL" />
      </geometry>
    </collision>
  </link>
  <joint
    name="Right_front_wheel_joint"
    type="continuous">
    <origin
      xyz="0.27184 0.0001 -0.028906"
      rpy="1.5708 0 1.5708" />
    <parent
      link="Chassis_front_beam" />
    <child
      link="Right_front_wheel" />
    <axis
      xyz="0 0 -1" />
  </joint>
  <link
    name="Left_front_wheel">
    <inertial>
      <origin
        xyz="-7.0038E-05 8.4129E-05 0.54476"
        rpy="0 0 0" />
      <mass
        value="1.25" />
      <inertia
        ixx="0.0049"
        ixy="0"
        ixz="0"
        iyy="0.005"
        iyz="0"
        izz="0.0087" />
    </inertial>
    <visual>
      <origin
        xyz="0 0 0.017"
        rpy="0 0 0" />
      <geometry>
        <mesh
          filename="package://segway_e1_description/meshes/Wheel.STL" />
      </geometry>
      <material
        name="">
        <color
          rgba="0.79216 0.81961 0.93333 1" />
      </material>
    </visual>
    <collision>
      <origin
        xyz="0 0 0"
        rpy="0 0 0" />
      <geometry>
        <mesh
          filename="package://segway_e1_description/meshes/Wheel.STL" />
      </geometry>
    </collision>
  </link>
  <joint
    name="Left_front_wheel_joint"
    type="continuous">
    <origin
      xyz="-0.27184 0.0001 -0.028906"
      rpy="1.5708 0 1.5708" />
    <parent
      link="Chassis_front_beam" />
    <child
      link="Left_front_wheel" />
    <axis
      xyz="0 0 -1" />
  </joint>

   <transmission name="Right_front_wheel_trans">
    <type>transmission_interface/SimpleTransmission</type>
    <joint name="Right_front_wheel_joint">
        <hardwareInterface>hardware_interface/EffortJointInterface</hardwareInterface>
    </joint>
    <actuator name="Right_front_wheel_motor">
        <hardwareInterface>hardware_interface/EffortJointInterface</hardwareInterface>
        <mechanicalReduction>1</mechanicalReduction>
    </actuator>
  </transmission>

    <transmission name="Left_front_wheel_trans">
    <type>transmission_interface/SimpleTransmission</type>
    <joint name="Left_front_wheel_joint">
        <hardwareInterface>hardware_interface/EffortJointInterface</hardwareInterface>
    </joint>
    <actuator name="Left_front_wheel_motor">
        <hardwareInterface>hardware_interface/EffortJointInterface</hardwareInterface>
        <mechanicalReduction>1</mechanicalReduction>
    </actuator>
  </transmission>

    <transmission name="Left_rear_wheel_trans">
    <type>transmission_interface/SimpleTransmission</type>
    <joint name="Left_rear_wheel_joint">
        <hardwareInterface>hardware_interface/EffortJointInterface</hardwareInterface>
    </joint>
    <actuator name="Left_rear_wheel_motor">
        <hardwareInterface>hardware_interface/EffortJointInterface</hardwareInterface>
        <mechanicalReduction>1</mechanicalReduction>
    </actuator>
  </transmission>

    <transmission name="Right_rear_wheel_trans">
    <type>transmission_interface/SimpleTransmission</type>
    <joint name="Right_rear_wheel_joint">
        <hardwareInterface>hardware_interface/EffortJointInterface</hardwareInterface>
    </joint>
    <actuator name="Right_rear_wheel_motor">
        <hardwareInterface>hardware_interface/EffortJointInterface</hardwareInterface>
        <mechanicalReduction>1</mechanicalReduction>
    </actuator>
  </transmission>

    <transmission name="Chassis_front_beam_trans">
    <type>transmission_interface/SimpleTransmission</type>
    <joint name="Chassis_front_beam_joint">
        <hardwareInterface>hardware_interface/EffortJointInterface</hardwareInterface>
    </joint>
    <actuator name="Chassis_front_beam_motor">
        <hardwareInterface>hardware_interface/EffortJointInterface</hardwareInterface>
        <mechanicalReduction>1</mechanicalReduction>
    </actuator>
  </transmission>
  <!-- <transmission name="${name}_transmission" type="SimpleTransmission">
    <type>transmission_interface/SimpleTransmission</type>
    <joint name="${name}_joint">
      <hardwareInterface>hardware_interface/VelocityJointInterface</hardwareInterface>
    </joint>
    <actuator name="${name}_motor">
      <hardwareInterface>hardware_interface/EffortJointInterface</hardwareInterface>
      <mechanicalReduction>1</mechanicalReduction>
    </actuator>
  </transmission> -->

  <link name="laser">
        <visual>
            <geometry>
                <cylinder radius="0.03" length="0.05" />
            </geometry>
            <origin xyz="0.0 0.0 0.0" rpy="0.0 0.0 0.0" />
            <material name="black" />
        </visual>
        <collision>
            <geometry>
                <cylinder radius="0.03" length="0.05" />
            </geometry>
            <origin xyz="0.0 0.0 0.0" rpy="0.0 0.0 0.0" />
        </collision>
        <inertial>
            <origin xyz="0 0 0" rpy="0 0 0" />
      <mass value="0.1" />
        <inertia
          ixx="0.0"
          ixy="0.0"
          ixz="0.0"
          iyy="0.0"
          iyz="0.0"
          izz="0.0" />
        </inertial>
    </link>

    <joint name="laser2base_link" type="fixed">
        <parent link="base_link" />
        <child link="laser" />
        <origin xyz="0.0 0.0 0.12" />
    </joint>

  <gazebo reference="laser">
    <sensor type="ray" name="rplidar">
      <pose>0 0 0 0 0 0</pose>
      <visualize>true</visualize>
      <update_rate>5.5</update_rate>
      <ray>
        <scan>
          <horizontal>
            <samples>360</samples>
            <resolution>1</resolution>
            <min_angle>-3</min_angle>
            <max_angle>3</max_angle>
          </horizontal>
        </scan>
        <range>
          <min>0.10</min>
          <max>30.0</max>
          <resolution>0.01</resolution>
        </range>
        <noise>
          <type>gaussian</type>
          <mean>0.0</mean>
          <stddev>0.01</stddev>
        </noise>
      </ray>
      <plugin name="gazebo_rplidar" filename="libgazebo_ros_laser.so">
        <topicName>/scan</topicName>
        <frameName>laser</frameName>
      </plugin>
    </sensor>
  </gazebo>

  <gazebo>
  <plugin name="gazebo_ros_control" filename="libgazebo_ros_control.so">
    <robotNamespace>/racebot</robotNamespace>
    <robotParam>robot_description</robotParam>
    <robotSimType>gazebo_ros_control/DefaultRobotHWSim</robotSimType>
    <legacyModeNS>true</legacyModeNS>
  </plugin>
  </gazebo> 

  <!-- <gazebo>
    <plugin name="skid_steer_drive_controller" filename="libgazebo_ros_skid_steer_drive.so">
        <updateRate>100.0</updateRate>
        <robotNamespace>/</robotNamespace>
        <leftFrontJoint>Left_front_wheel_joint</leftFrontJoint>
        <rightFrontJoint>Right_front_wheel_joint</rightFrontJoint>
        <leftRearJoint>Left_rear_wheel_joint</leftRearJoint>
        <rightRearJoint>Right_rear_wheel_joint</rightRearJoint>
        <wheelSeparation>0.492</wheelSeparation>
        <wheelDiameter>0.216</wheelDiameter>
        <robotBaseFrame>base_footprint</robotBaseFrame>
        <torque>20</torque>
        <topicName>cmd_vel</topicName>
        <broadcastTF>false</broadcastTF>
        <odometryFrame>odom</odometryFrame>
        <odometryTopic>odom</odometryTopic> 
       <robotBaseFrame>base_footprint</robotBaseFrame>
       <publishTf>1</publishTf>
    </plugin>
  </gazebo> -->

    <!-- <gazebo>
        <plugin name="differential_drive_controller" filename="libgazebo_ros_diff_drive.so">
            <rosDebugLevel>Debug</rosDebugLevel>
            <publishWheelTF>False</publishWheelTF>
            <robotNamespace>/</robotNamespace>
            <publishTf>1</publishTf>
            <publishWheelJointState>False</publishWheelJointState>
            <alwaysOn>true</alwaysOn>
            <updateRate>100.0</updateRate>
            <legacyMode>true</legacyMode>
            <leftJoint>Left_front_wheel_joint</leftJoint> 
            <rightJoint>Right_front_wheel_joint</rightJoint> 
            <wheelSeparation>0.492</wheelSeparation> 
            <wheelDiameter>0.216</wheelDiameter> 
            <broadcastTF>1</broadcastTF>
            <wheelTorque>30</wheelTorque>
            <wheelAcceleration>1.8</wheelAcceleration>
            <commandTopic>cmd_vel</commandTopic> 
            <odometryFrame>odom</odometryFrame>
            <odometryTopic>odom</odometryTopic> 
            <robotBaseFrame>base_footprint</robotBaseFrame> 
        </plugin>
    </gazebo> -->

    <!-- <gazebo>
        <plugin name="differential_drive_controller" filename="libgazebo_ros_diff_drive.so">
            <rosDebugLevel>Debug</rosDebugLevel>
            <publishWheelTF>False</publishWheelTF>
            <robotNamespace>/</robotNamespace>
            <publishTf>1</publishTf>
            <publishWheelJointState>False</publishWheelJointState>
            <alwaysOn>true</alwaysOn>
            <updateRate>100.0</updateRate>
            <legacyMode>true</legacyMode>
            <leftJoint>Left_rear_wheel_joint</leftJoint> 
            <rightJoint>Right_rear_wheel_joint</rightJoint> 
            <wheelSeparation>0.545</wheelSeparation> 
            <wheelDiameter>0.216</wheelDiameter> 
            <broadcastTF>1</broadcastTF>
            <wheelTorque>30</wheelTorque>
            <wheelAcceleration>1.8</wheelAcceleration>
            <commandTopic>cmd_vel</commandTopic> 
            <odometryFrame>odom</odometryFrame>
            <odometryTopic>odom</odometryTopic> 
            <robotBaseFrame>base_footprint</robotBaseFrame> 
        </plugin>
    </gazebo> -->
</robot>